cd mount 


DEBUG:fuse.log-mixin:-> getattr / (None,)
DEBUG:fuse.log-mixin:<- getattr {'st_atime': 1601521110.04, 'st_ctime': 1601521109.25, 'st_gid': 1000, 'st_mode': 16877, 'st_mtime': 1601521109.25, 'st_nlink': 2, 'st_size': 4096, 'st_uid': 1000}
DEBUG:fuse.log-mixin:-> access / (1,)
DEBUG:fuse.log-mixin:<- access None




cat > newfile 


DEBUG:fuse.log-mixin:-> getattr / (None,)
DEBUG:fuse.log-mixin:<- getattr {'st_atime': 1601521110.04, 'st_ctime': 1601521109.25, 'st_gid': 1000, 'st_mode': 16877, 'st_mtime': 1601521109.25, 'st_nlink': 2, 'st_size': 4096, 'st_uid': 1000}
DEBUG:fuse.log-mixin:-> getattr /newfile (None,)
DEBUG:fuse.log-mixin:<- getattr "[Errno 2] No such file or directory: 'source/newfile'"
DEBUG:fuse:FUSE operation getattr raised a <class 'FileNotFoundError'>, returning errno 2.
Traceback (most recent call last):
  File "/home/jack/SE370A2/fuse.py", line 731, in _wrapper
    return func(*args, **kwargs) or 0
  File "/home/jack/SE370A2/fuse.py", line 771, in getattr
    return self.fgetattr(path, buf, None)
  File "/home/jack/SE370A2/fuse.py", line 1024, in fgetattr
    attrs = self.operations('getattr', self._decode_optional_path(path), fh)
  File "/home/jack/SE370A2/fuse.py", line 1240, in __call__
    ret = getattr(self, op)(path, *args)
  File "/home/jack/SE370A2/passthrough.py", line 43, in getattr
    st = os.lstat(full_path)
FileNotFoundError: [Errno 2] No such file or directory: 'source/newfile'
DEBUG:fuse.log-mixin:-> create /newfile (33188,)
DEBUG:fuse.log-mixin:<- create 4
DEBUG:fuse.log-mixin:-> getattr /newfile (4,)
DEBUG:fuse.log-mixin:<- getattr {'st_atime': 1601521307.29, 'st_ctime': 1601521307.29, 'st_gid': 1000, 'st_mode': 33188, 'st_mtime': 1601521307.29, 'st_nlink': 1, 'st_size': 0, 'st_uid': 1000}
DEBUG:fuse.log-mixin:-> flush /newfile (4,)
DEBUG:fuse.log-mixin:<- flush None
DEBUG:fuse.log-mixin:-> getattr / (None,)
DEBUG:fuse.log-mixin:<- getattr {'st_atime': 1601521307.29, 'st_ctime': 1601521307.29, 'st_gid': 1000, 'st_mode': 16877, 'st_mtime': 1601521307.29, 'st_nlink': 2, 'st_size': 4096, 'st_uid': 1000}
DEBUG:fuse.log-mixin:-> opendir / ()
DEBUG:fuse.log-mixin:<- opendir 0
DEBUG:fuse.log-mixin:-> readdir / (0,)
DEBUG:fuse.log-mixin:<- readdir <generator object Passthrough.readdir at 0x7fa8aad89dd0>
DEBUG:fuse.log-mixin:-> releasedir / (0,)
DEBUG:fuse.log-mixin:<- releasedir 0
DEBUG:fuse.log-mixin:-> getattr /one (None,)
DEBUG:fuse.log-mixin:<- getattr {'st_atime': 1601470779.13, 'st_ctime': 1601470763.1, 'st_gid': 1000, 'st_mode': 33188, 'st_mtime': 1601470763.117, 'st_nlink': 1, 'st_size': 2, 'st_uid': 1000}
DEBUG:fuse.log-mixin:-> getattr /three (None,)
DEBUG:fuse.log-mixin:<- getattr {'st_atime': 1601470762.89, 'st_ctime': 1601470762.86, 'st_gid': 1000, 'st_mode': 33188, 'st_mtime': 1601470762.873, 'st_nlink': 1, 'st_size': 2, 'st_uid': 1000}
DEBUG:fuse.log-mixin:-> getattr /two (None,)
DEBUG:fuse.log-mixin:<- getattr {'st_atime': 1601470779.13, 'st_ctime': 1601470763.02, 'st_gid': 1000, 'st_mode': 33188, 'st_mtime': 1601470763.022, 'st_nlink': 1, 'st_size': 2, 'st_uid': 1000}
DEBUG:fuse.log-mixin:-> getattr / (None,)
DEBUG:fuse.log-mixin:<- getattr {'st_atime': 1601521308.12, 'st_ctime': 1601521307.29, 'st_gid': 1000, 'st_mode': 16877, 'st_mtime': 1601521307.29, 'st_nlink': 2, 'st_size': 4096, 'st_uid': 1000}
DEBUG:fuse.log-mixin:-> getattr /.gitignore (None,)
DEBUG:fuse.log-mixin:<- getattr "[Errno 2] No such file or directory: 'source/.gitignore'"
DEBUG:fuse:FUSE operation getattr raised a <class 'FileNotFoundError'>, returning errno 2.
Traceback (most recent call last):
  File "/home/jack/SE370A2/fuse.py", line 731, in _wrapper
    return func(*args, **kwargs) or 0
  File "/home/jack/SE370A2/fuse.py", line 771, in getattr
    return self.fgetattr(path, buf, None)
  File "/home/jack/SE370A2/fuse.py", line 1024, in fgetattr
    attrs = self.operations('getattr', self._decode_optional_path(path), fh)
  File "/home/jack/SE370A2/fuse.py", line 1240, in __call__
    ret = getattr(self, op)(path, *args)
  File "/home/jack/SE370A2/passthrough.py", line 43, in getattr
    st = os.lstat(full_path)
FileNotFoundError: [Errno 2] No such file or directory: 'source/.gitignore'
DEBUG:fuse.log-mixin:-> getattr /newfile (None,)
DEBUG:fuse.log-mixin:<- getattr {'st_atime': 1601521307.29, 'st_ctime': 1601521307.29, 'st_gid': 1000, 'st_mode': 33188, 'st_mtime': 1601521307.29, 'st_nlink': 1, 'st_size': 0, 'st_uid': 1000}



hello world


DEBUG:fuse.log-mixin:-> getxattr /newfile ('security.capability',)
DEBUG:fuse.log-mixin:<- getxattr '[Errno 95] Operation not supported'
DEBUG:fuse:FUSE operation getxattr raised a <class 'fuse.FuseOSError'>, returning errno 95.
Traceback (most recent call last):
  File "/home/jack/SE370A2/fuse.py", line 731, in _wrapper
    return func(*args, **kwargs) or 0
  File "/home/jack/SE370A2/fuse.py", line 906, in getxattr
    ret = self.operations('getxattr', path.decode(self.encoding),
  File "/home/jack/SE370A2/fuse.py", line 1240, in __call__
    ret = getattr(self, op)(path, *args)
  File "/home/jack/SE370A2/fuse.py", line 1124, in getxattr
    raise FuseOSError(ENOTSUP)
fuse.FuseOSError: [Errno 95] Operation not supported
DEBUG:fuse.log-mixin:-> write /newfile (b'hello word\n', 0, 4)
DEBUG:fuse.log-mixin:<- write 11



^D


DEBUG:fuse.log-mixin:-> flush /newfile (4,)
DEBUG:fuse.log-mixin:<- flush None
DEBUG:fuse.log-mixin:-> release /newfile (4,)
DEBUG:fuse.log-mixin:<- release None


cd ../

DEBUG:fuse.log-mixin:-> getattr / (None,)
DEBUG:fuse.log-mixin:<- getattr {'st_atime': 1601521308.12, 'st_ctime': 1601521307.29, 'st_gid': 1000, 'st_mode': 16877, 'st_mtime': 1601521307.29, 'st_nlink': 2, 'st_size': 4096, 'st_uid': 1000}



fusermount -u mount


DEBUG:fuse.log-mixin:-> destroy / ()
DEBUG:fuse.log-mixin:<- destroy None


ls and output content of source and mount dirs











